Workbook

Sheet High School Players
E1: =iferror(IFS(M1="RHP","RHP",M1="LHP","LHP",M1="C","C",M1="CINF","INF",M1="MINF","INF",M1="COF","OF",M1="CF","OF",M1="1B","INF",M1="2B","INF",M1="3B","INF",M1="OF","OF",M1="INF","INF",M1="SS","INF"),"") | H1: HS PLAYERS | K1: 0.1 Committed 1 Offer 2 High Follow 3 Follow 4 Need to see 5 XX | AJ1: Filter out blanks, then copy paste changes into column K
K2: Filter A-Z | AB2: AUTO PULL FROM RECRUITING FORM
B3: Tier | C3: ID | D3: Name | E3: Pos Group | F3: Date Added: | G3: By: | H3: First Name | I3: Last Name | J3: Class | K3: ★ | L3: Commit | M3: Pos | N3: POS2 | O3: B/T | P3: Hometown | Q3: State | R3: High School | S3: Summer Team | T3: Academic | U3: Email | V3: Phone Number | W3: Seen | X3: Visit Date | Y3: Offer Date | Z3: Comms | AA3: Notes | AB3: Email | AC3: Baseball Statistics(Please insert HS season stats)/Accolades (High School & Summer if available) | AD3: GPA (Unweighted/Weighted) | AE3: Test Scores (SAT/ACT or both) please list. | AF3: Injury History - Please list any sport specific injuries and/or surgeries you have had. | AG3: Do you have any allergies to foods and/or medications? If yes, please list them below. | AH3: Are you currently taking any medications? If yes, please list them below. | AI3: Do you require any academic accommodations(i.e. extra time on tests)? | AJ3: Update ★
B4: 1 | C4: =IFERROR(__xludf.DUMMYFUNCTION("MAP(D4:D2085, K4:K2085, J4:J2085, M4:M2085, Q4:Q2085, LAMBDA(c, k, j, m, q, IF(c="""", """", IFERROR(c & "" ("" & k & "") - "" & ""'2"" & SPLIT(j,""20"") & "" "" & m) & "" "" & q ) ) )"),"John Loudon (0.1) - '25 COF GA") -> John Loudon (0.1) - '25 COF GA | D4: {=MAP(H4:H2085, I4:I2085, LAMBDA(h, i, IF(h="", "", h & " " & i) ) )} -> John Loudon | E4: {=MAP(M4:M2085, LAMBDA(m, IF(m="", "", IFERROR(IFS( m="RHP","RHP", m="LHP","LHP", m="C","C", m="CINF","INF", m="MINF","INF", m="COF","OF", m="CF","OF", m="1B","INF", m="2B","INF", m="3B","INF", m="OF","OF", m="INF","INF", m="SS","INF" ),"") ) ) )} -> OF | H4: John | I4: Loudon | J4: 2025 | K4: 0.1 | L4: NAVY | M4: COF | Q4: GA | R4: Marist | S4: 9th INN Royals | X4: 45937 | AA4: 8/1 Call - Asked great questions. Genuine interest, gpop was army and has talked him into servoce. Had a lot of traffoc today. Need to get on visit asap.AP: Futures. 5'11 190 avg. +SPEED. 6.5 runner. compact swing with decent bat speed. strong body. TR - Lit up the WWBA in the summer. Showed power and an advanced approach at the plate. Swung it well off canes national team. Stole bases at will and had very athletic actions in the outfield. | AB4: {=MAP($D4:$D2085, LAMBDA(d, IF(d="", "", XLOOKUP(d, 'Recruiting Form Responses'!$C:$C, 'Recruiting Form Responses'!D:D, "", 0, 1) ) ) )} | AC4: {=MAP($D4:$D2085, LAMBDA(d, IF(d="", "", XLOOKUP(d, 'Recruiting Form Responses'!$C:$C, 'Recruiting Form Responses'!G:G, "", 0, 1) ) ) )} | AD4: {=MAP($D4:$D2085, LAMBDA(d, IF(d="", "", XLOOKUP(d, 'Recruiting Form Responses'!$C:$C, 'Recruiting Form Responses'!H:H, "", 0, 1) ) ) )} | AE4: {=MAP($D4:$D2085, LAMBDA(d, IF(d="", "", XLOOKUP(d, 'Recruiting Form Responses'!$C:$C, 'Recruiting Form Responses'!I:I, "", 0, 1) ) ) )} | AF4: {=MAP($D4:$D2085, LAMBDA(d, IF(d="", "", XLOOKUP(d, 'Recruiting Form Responses'!$C:$C, 'Recruiting Form Responses'!J:J, "", 0, 1) ) ) )} | AG4: {=MAP($D4:$D2085, LAMBDA(d, IF(d="", "", XLOOKUP(d, 'Recruiting Form Responses'!$C:$C, 'Recruiting Form Responses'!K:K, "", 0, 1) ) ) )} | AH4: {=MAP($D4:$D2085, LAMBDA(d, IF(d="", "", XLOOKUP(d, 'Recruiting Form Responses'!$C:$C, 'Recruiting Form Responses'!L:L, "", 0, 1) ) ) )} | AI4: {=MAP($D4:$D2085, LAMBDA(d, IF(d="", "", XLOOKUP(d, 'Recruiting Form Responses'!$C:$C, 'Recruiting Form Responses'!M:M, "", 0, 1) ) ) )} | AJ4: {=MAP($D4:$D2085, LAMBDA(d, IF(d="", "", XLOOKUP(d, StarUpdater!$A:$A, StarUpdater!D:D, "", 0, 1) ) ) )}
B5: 1 | C5: =IFERROR(__xludf.DUMMYFUNCTION("""COMPUTED_VALUE"""),"Noah Stead (0.1) - '25 MINF CA") -> Noah Stead (0.1) - '25 MINF CA | D5: Noah Stead | E5: INF | H5: Noah | I5: Stead | J5: 2025 | K5: 0.1 | L5: NAVY | M5: MINF | Q5: CA | R5: Westlake | S5: So Cal Giants | X5: 45527 | AA5: TR: Dude day. Moves well very good hands separates the ball below his knees. enough arm to play ss with a quick release. Unorthodox swing but gets on plane and has really good bat to ball. Power and extrra base hit guy. .320 with 7 HRs in HS. HS and summer coach both say all the right things about kid and parents. Going to hit 3rd and play ss at Westlake HS this year. was the only junior in an all senior d1 committed lineup last year. Ready to offer. | AB5: Steadnoah5@gmail.com | AC5: All Ventura County First Team/ Scholar Athlete 2 Years/ Offensive Player of the Year for Varsity | AD5: 4.0 Weighted | AE5: None Yet. Taking in November | AF5: None | AG5: None | AH5: None | AI5: None
B6: 1 | C6: =IFERROR(__xludf.DUMMYFUNCTION("""COMPUTED_VALUE"""),"Owen Phypers (0.1) - '25 RHP FL") -> Owen Phypers (0.1) - '25 RHP FL | D6: Owen Phypers | E6: RHP | H6: Owen | I6: Phypers | J6: 2025 | K6: 0.1 | L6: NAVY | M6: RHP | Q6: FL | R6: St. John Neumann | S6: Florida Burn | X6: 45474
B7: 1 | C7: =IFERROR(__xludf.DUMMYFUNCTION("""COMPUTED_VALUE"""),"Patrick Walsh (0.1) - '25 CINF NC") -> Patrick Walsh (0.1) - '25 CINF NC | D7: Patrick Walsh | E7: INF | H7: Patrick | I7: Walsh | J7: 2025 | K7: 0.1 | L7: NAVY | M7: CINF | Q7: NC | R7: Christ the king Catholic | S7: wow factor | AA7: 6'1 195 strong LHH. Manning comp. Avg run 4.3 down the line. Power potential in bat. Fringe def. Good arm. Was 87-89 (91) at June Navy prospect camp. Performace history good. POTY in 1A conference. | AB7: walsh.patrick.2025@gmail.com | AC7: Slash Line: 0.487/0.610/1.064 2B: 10 3B: 4 HR: 9 RBI: 38 SB: 13 BB: 22 R: 36 GP:28 PA: 105 Pitching IP: 38.2 ERA: 3.44 K:56 2024 CSAC CPOY 2024 NCBA 1st Team All-State 2024 Charlotte Observer 1st Team All-Area | AD7: 4.44 | AE7: SAT:1230 ACT: Not yet Taken | AF7: No Baseball Related injuries. MLC Sprain in October 2023 playing football. Hamstring avulsion playing football in August 2022. | AG7: No | AH7: No | AI7: No
B8: 1 | C8: =IFERROR(__xludf.DUMMYFUNCTION("""COMPUTED_VALUE"""),"Sachin Gopal (0.1) - '25 RHP MA") -> Sachin Gopal (0.1) - '25 RHP MA | D8: Sachin Gopal | E8: RHP | H8: Sachin | I8: Gopal | J8: 2025 | K8: 0.1 | L8: NAVY | M8: RHP | Q8: MA | R8: Dexter Southfield | S8: Nokona | X8: 45461 | AB8: sachingopal@yahoo.com | AC8: This High school season: CNEPSBL all star and All NEPSAC HM, 31IP 30K 6BB 1.58ERA .935 WHIP .200 BAA. Last Summer: 40IP (3 CG’s), 45K, 11BB, 1.75 ERA, .950 WHIP, and a .180 BAA. | AD8: 3.7 UW | AE8: 1420 SAT | AF8: No injuries | AG8: No allergies | AH8: No medication | AI8: I am eligible for accommodations but don’t actually use them or need them
B9: 1 | C9: =IFERROR(__xludf.DUMMYFUNCTION("""COMPUTED_VALUE"""),"Sinjon Lash (0.1) - '25 RHP GA") -> Sinjon Lash (0.1) - '25 RHP GA | D9: Sinjon Lash | E9: RHP | H9: Sinjon | I9: Lash | J9: 2025 | K9: 0.1 | L9: NAVY | M9: RHP | Q9: GA | R9: LaGrange HS | S9: Atlanta Braves Scout | X9: 45951 | AA9: AP: have not seen yet. 6'4 200 good frame. 85-88 w/ 75 CB, has CH. Talked with him on the phone and he seems interested. will see him throw this fall. moved to GA from WA few years ago. was with EC Astros but now with Titans (ATL Braves scout team)
B10: 1 | C10: =IFERROR(__xludf.DUMMYFUNCTION("""COMPUTED_VALUE"""),"Tyler Cripe (0.1) - '25 CF FL") -> Tyler Cripe (0.1) - '25 CF FL | D10: Tyler Cripe | E10: OF | H10: Tyler | I10: Cripe | J10: 2025 | K10: 0.1 | L10: NAVY | M10: CF | Q10: FL | R10: Florida Burn | X10: 45972 | AA10: JK-been in touch since his vist. High interest. Likely wants to commit. Allergy report came in on Dec 12. Looks like all allergies have subsided. Have to run up the chain. No reservations about the abililty/player. Questionable info on personality fit from HS coach. JK- Lean frame. Whippy barrel. Good runner/floats. K/F7/1b64
B11: 1 | C11: =IFERROR(__xludf.DUMMYFUNCTION("""COMPUTED_VALUE"""),"Will Howard (0.1) - '25 C KS") -> Will Howard (0.1) - '25 C KS | D11: Will Howard | E11: C | H11: Will | I11: Howard | J11: 2025 | K11: 0.1 | L11: NAVY | M11: C | Q11: KS | S11: Royals Scout Team | AA11: TR NPI: physical build moves well. Very good catch and throw 1.9-2.0 on the bag, quick release. Good stance and flex. Like the swing and athelticism in the box. Didn't get much offensive look need to see again. Good first call sounds very inetersted and has always wanted to serve. Very normal kid, hit .420 in HS with 4 HR. Looks like a string kid.
B12: 1 | C12: =IFERROR(__xludf.DUMMYFUNCTION("""COMPUTED_VALUE"""),"Ben Baldessare (2) - '25 MINF NC") -> Ben Baldessare (2) - '25 MINF NC | D12: Ben Baldessare | E12: INF | H12: Ben | I12: Baldessare | J12: 2025 | K12: 2 | M12: MINF | Q12: NC | R12: Providence | S12: Richmond braves | AA12: JK email notes: Top 500 #2 1B in NC.
B13: 1 | C13: =IFERROR(__xludf.DUMMYFUNCTION("""COMPUTED_VALUE"""),"Cal Travers (2) - '25 LHP VA") -> Cal Travers (2) - '25 LHP VA | D13: Cal Travers | E13: LHP | H13: Cal | I13: Travers | J13: 2025 | K13: 2 | M13: LHP | Q13: VA | R13: Godwin | S13: 101mph Dragum | AA13: TR: Spoke with Cal, had an offer from VMI. Didn't have a good spring, didn't pitch much told me he's 85-87 on FB 77-78 on SL. Told me he was inconsistent. Goldy told me he has a connection to the kid and that he was coming ot camp. JK email notes: High follow pg 17 ranked in VA. 6'1" 190
B14: 1 | C14: =IFERROR(__xludf.DUMMYFUNCTION("""COMPUTED_VALUE"""),"Eric Harrison (2) - '25 MINF FL") -> Eric Harrison (2) - '25 MINF FL | D14: Eric Harrison | E14: INF | H14: Eric | I14: Harrison | J14: 2025 | K14: 2 | M14: MINF | Q14: FL | R14: Avon Park | S14: Southern Squeeze | AA14: JK: Email notes: 8 on pg. 6'2" 215. High follow as 3rd baseman.
B15: 1 | C15: =IFERROR(__xludf.DUMMYFUNCTION("""COMPUTED_VALUE"""),"Jake Hooten (2) - '25 CF FL") -> Jake Hooten (2) - '25 CF FL | D15: Jake Hooten | E15: OF | H15: Jake | I15: Hooten | J15: 2025 | K15: 2 | M15: CF | Q15: FL | R15: Gulf Breeze | S15: East Coast Sox Scout | AA15: June Camp: 6'2 190 strong bodied and runs. Ran 6.7 and 6.8 at camp. Need to see how well bat plays | AB15: jr3hooten@gmail.com | AC15: 22 games .375 avg, .467 obp, .998 ops, 74PA, 24/64 hits/ab, 6 doubles, 2HR, 18R, 17rbi Team MVP, Pitching: 4-1 18 innings, 29k, .79 ERA | AD15: 4.83 | AE15: 34 ACT 1390 SAT | AF15: Broken ankle/screws; Broken finger | AG15: No | AH15: No | AI15: No
B16: 1 | C16: =IFERROR(__xludf.DUMMYFUNCTION("""COMPUTED_VALUE"""),"La'akea Correa (2) - '25 LHP HI") -> La'akea Correa (2) - '25 LHP HI | D16: La'akea Correa | E16: LHP | H16: La'akea | I16: Correa | J16: 2025 | K16: 2 | M16: LHP | Q16: HI | AA16: JK: 83-85, 72-74 spin, 74-75 CH, Fb to both sides for sure. CH can be solid. Spin is avg.
B17: 1 | C17: =IFERROR(__xludf.DUMMYFUNCTION("""COMPUTED_VALUE"""),"Lucas Collins (2) - '25 LHP IN") -> Lucas Collins (2) - '25 LHP IN | D17: Lucas Collins | E17: LHP | H17: Lucas | I17: Collins | J17: 2025 | K17: 2 | M17: LHP | Q17: IN | R17: Bishop dwenger | S17: Canes Midwest | AA17: JK email notes: up to 89 on pbr. #4 lhp in IN.
B18: 1 | C18: =IFERROR(__xludf.DUMMYFUNCTION("""COMPUTED_VALUE"""),"Michael Fiatrone (2) - '25 MINF CT") -> Michael Fiatrone (2) - '25 MINF CT | D18: Michael Fiatrone | E18: INF | H18: Michael | I18: Fiatrone | J18: 2025 | K18: 2 | M18: MINF | Q18: CT | R18: Salisbury School | AA18: JK- solid film. SS at Salisbury. Will see in spring. Saw briefly in FL. Liked the frame and actions. Didn't have a blowaway showing.
B19: 1 | C19: =IFERROR(__xludf.DUMMYFUNCTION("""COMPUTED_VALUE"""),"Nathan Lake (2) - '25 LHP VA") -> Nathan Lake (2) - '25 LHP VA | D19: Nathan Lake | E19: LHP | H19: Nathan | I19: Lake | J19: 2025 | K19: 2 | M19: LHP | Q19: VA | S19: VA Stars | AA19: JK-3 pitch/pitchability LHP. Wont wow but can pitch a bit. High int in academy. Would like second set of eyes on him | AB19: Nathan.lake@outlook.com | AC19: 1.4 era 1st team all district | AD19: 3.8 | AE19: 1180 | AG19: No | AH19: Claritin | AI19: No
B20: 1 | C20: =IFERROR(__xludf.DUMMYFUNCTION("""COMPUTED_VALUE"""),"Sam Harry (2) - '25 COF CO") -> Sam Harry (2) - '25 COF CO | D20: Sam Harry | E20: OF | H20: Sam | I20: Harry | J20: 2025 | K20: 2 | M20: COF | Q20: CO | R20: Castle View | AA20: TR: Watched at Slammers event. He has a pro body 4.6 on turn and 4.3/3 through the base. Runs and moves like a big leaguer. Swing is atheltic but was not making good contact early in the weekend when he lets it go its an atheltic and quick swing. His numbers from HS were .456 w/ 9k/6bb. Only 1 HR in CO. I'm worried about power, his approach is to drive the ball the other way and he may be able to do that well. Holz told me he was about to commit to Charleston So. and mom dragged it out trying to get more money. They gave him 3k more and the coaching change happened. Kuhn told him they can't take his commitment now but theyre goign to watch him. Dad wears pins on his crocs.
B21: 1 | C21: =IFERROR(__xludf.DUMMYFUNCTION("""COMPUTED_VALUE"""),"Tate Elliott (2) - '25 C TX") -> Tate Elliott (2) - '25 C TX | D21: Tate Elliott | E21: C | H21: Tate | I21: Elliott | J21: 2025 | K21: 2 | M21: C | Q21: TX | R21: Midlothian | S21: TBT Texas | AA21: JK: Can really throw. athletic frame. hands probably not as good as wells but throws better. avg runner. Worried about bat. | AB21: tateelliott1131@gmail.com | AC21: Preseason All American, All district, Texas 5a All star | AD21: 3.5 | AE21: 1070
B22: 1 | C22: =IFERROR(__xludf.DUMMYFUNCTION("""COMPUTED_VALUE"""),"Trent Prosperi (2) - '25 MINF TX") -> Trent Prosperi (2) - '25 MINF TX | D22: Trent Prosperi | E22: INF | H22: Trent | I22: Prosperi | J22: 2025 | K22: 2 | M22: MINF | Q22: TX | R22: Boswell HS | S22: Cooperstown Cobras | AA22: JK: HIt 2. Like this kid but playing 2B. Good turns, barrell contact. Does he have enough arm for left side???
B23: 1 | C23: =IFERROR(__xludf.DUMMYFUNCTION("""COMPUTED_VALUE"""),"Aiden Szydlik (3) - '25 MINF MD") -> Aiden Szydlik (3) - '25 MINF MD | D23: Aiden Szydlik | E23: INF | H23: Aiden | I23: Szydlik | J23: 2025 | K23: 3 | M23: MINF | Q23: MD | R23: Severn School | S23: Canes Mid Atlantic | AA23: JK-physical switch hitting IF/possible corner OF. Elite student. Parents are W.Point grads but the kid seems really interested in Navy
B24: 1 | C24: =IFERROR(__xludf.DUMMYFUNCTION("""COMPUTED_VALUE"""),"Ayden Munoz (3) - '25 COF CA") -> Ayden Munoz (3) - '25 COF CA | D24: Ayden Munoz | E24: OF | H24: Ayden | I24: Munoz | J24: 2025 | K24: 3 | M24: COF | Q24: CA | R24: Carlsbad | S24: So Cal Giants | AA24: AP: 5'9 170, very small. LHH with a good swing and good bat speed. low ceiling bc/ of size. athletic.6.7 runner
B25: 1 | C25: =IFERROR(__xludf.DUMMYFUNCTION("""COMPUTED_VALUE"""),"Benjy Cardone (3) - '25 C VA") -> Benjy Cardone (3) - '25 C VA | D25: Benjy Cardone | E25: C | H25: Benjy | I25: Cardone | J25: 2025 | K25: 3 | M25: C | Q25: VA | R25: Highland HS | X25: 45952 | AA25: Hit .276 JR yr. AP: update: high motor, vocal player, good skills behind the dish with quick release. avg arm. good swing with doubles pwr. doesnt run. ceiling limited bc of size. offensive comp eddie Diaz. JK-been in contact via text/email. Dad is CIA. Solid catch/release. Arm has carry. Showed pop in BP despite more compact frame. Reminds me of Killelea a bit. Really good kid on visit. Has his shit together. JK-has continued to keep in touch.
B26: 1 | C26: =IFERROR(__xludf.DUMMYFUNCTION("""COMPUTED_VALUE"""),"Bobby Herzman (3) - '25 CINF CT") -> Bobby Herzman (3) - '25 CINF CT | D26: Bobby Herzman | E26: INF | H26: Bobby | I26: Herzman | J26: 2025 | K26: 3 | M26: CINF | Q26: CT | R26: HC Wilcox | AA26: AP: Futures. not a need right now. 6'2 235, big boy/softer body right now. 1B only: LHH who gets his swing off. good bat speed and good swing. looks good in the box, feel for hitting/approach. avg def. avg arm. 7.8 not a runner.
B27: 1 | C27: =IFERROR(__xludf.DUMMYFUNCTION("""COMPUTED_VALUE"""),"Braxton Graber (3) - '25 RHP AR") -> Braxton Graber (3) - '25 RHP AR | D27: Braxton Graber | E27: RHP | H27: Braxton | I27: Graber | J27: 2025 | K27: 3 | M27: RHP | Q27: AR | R27: East Coast SandHogs | AA27: JK-85-86/spin 72 12/6 shape. Loose arm/clean
B28: 1 | C28: =IFERROR(__xludf.DUMMYFUNCTION("""COMPUTED_VALUE"""),"Brooks Bradshaw (3) - '25 RHP GA") -> Brooks Bradshaw (3) - '25 RHP GA | D28: Brooks Bradshaw | E28: RHP | H28: Brooks | I28: Bradshaw | J28: 2025 | K28: 3 | M28: RHP | Q28: GA | R28: Benedictine Military | S28: CBU Stofsky | AA28: JK email notes: 6'3" 205 pg top 1000.
B29: 1 | C29: =IFERROR(__xludf.DUMMYFUNCTION("""COMPUTED_VALUE"""),"Caden Davidson (3) - '25 MINF NC") -> Caden Davidson (3) - '25 MINF NC | D29: Caden Davidson | E29: INF | H29: Caden | I29: Davidson | J29: 2025 | K29: 3 | M29: MINF | Q29: NC | R29: USA Prime Coastal | S29: 5 Star | AA29: JK-physical kid. Didn't see enough to weigh in. Need to see more if interest. #7 3b in NC.
B30: 1 | C30: =IFERROR(__xludf.DUMMYFUNCTION("""COMPUTED_VALUE"""),"Colton Roberts (3) - '25 RHP KS") -> Colton Roberts (3) - '25 RHP KS | D30: Colton Roberts | E30: RHP | H30: Colton | I30: Roberts | J30: 2025 | K30: 3 | M30: RHP | Q30: KS | R30: Rose Hill | AA30: TR- texted 1/3 to connect. Futures. 87-89 / 75. Loose quick arm. Ath feel for spin. Presence and poise.
B31: 1 | C31: =IFERROR(__xludf.DUMMYFUNCTION("""COMPUTED_VALUE"""),"Cy Herkelroath (3) - '25 LHP PA") -> Cy Herkelroath (3) - '25 LHP PA | D31: Cy Herkelroath | E31: LHP | H31: Cy | I31: Herkelroath | J31: 2025 | K31: 3 | M31: LHP | Q31: PA | R31: TOPS | S31: Elizabeth Forward | AA31: JK email notes: High follow 6'3" 200. #11 lhp in state
B32: 1 | C32: =IFERROR(__xludf.DUMMYFUNCTION("""COMPUTED_VALUE"""),"Davis Beilstein (3) - '25 COF GA") -> Davis Beilstein (3) - '25 COF GA | D32: Davis Beilstein | E32: OF | H32: Davis | I32: Beilstein | J32: 2025 | K32: 3 | M32: COF | Q32: GA | R32: 643 | AA32: JK-strong interest in Navy. Listed as a C but likely corner OF. Physical frame. Have to see if he hits enough to even consider.
B33: 1 | C33: =IFERROR(__xludf.DUMMYFUNCTION("""COMPUTED_VALUE"""),"Drew Flores (3) - '25 C TX") -> Drew Flores (3) - '25 C TX | D33: Drew Flores | E33: C | H33: Drew | I33: Flores | J33: 2025 | K33: 3 | M33: C | Q33: TX | R33: 5 star performance national | AA33: JK: Could be catcher in the mix. Check in on him
B34: 1 | C34: =IFERROR(__xludf.DUMMYFUNCTION("""COMPUTED_VALUE"""),"Drew Kindlon (3) - '25 RHP NY") -> Drew Kindlon (3) - '25 RHP NY | D34: Drew Kindlon | E34: RHP | H34: Drew | I34: Kindlon | J34: 2025 | K34: 3 | M34: RHP | Q34: NY | R34: P27 Academy | AA34: AP: update, 82-86, not great looking in short outing. arm tightened up and exited game. TR: recommended by Josh Murphy. Decommitt from UVA. Looks like a high level arm with a high level brekaign ball and plus spin on FB. 6'3" 210 pg 9. Josh told me he is coming off a back injury but recent videos look very good. Have reached out to kid. Recruiting heating up have to see Fri PBR 17U | AB34: kindlondrew632@gmail.com | AD34: 3.8 | AE34: 1240 | AF34: Ucl strain Back fracture | AG34: No | AH34: No | AI34: No
B35: 1 | C35: =IFERROR(__xludf.DUMMYFUNCTION("""COMPUTED_VALUE"""),"Drew McTagertt (3) - '25 C IN") -> Drew McTagertt (3) - '25 C IN | D35: Drew McTagertt | E35: C | H35: Drew | I35: McTagertt | J35: 2025 | K35: 3 | M35: C | Q35: IN | R35: William Henry Harrison | S35: Indiana Bulls | AA35: AP: update: has not gotten stronger, maybe backtracked strength wise. 6'3 180 good body. didn't see a ton from him. Future Games kid. their coaches like him. JK- saw briefly in FL. Good enough to reach out/gauge interest/see again if he is a fit.
B36: 1 | C36: =IFERROR(__xludf.DUMMYFUNCTION("""COMPUTED_VALUE"""),"Ethan Johnson (3) - '25 MINF CA") -> Ethan Johnson (3) - '25 MINF CA | D36: Ethan Johnson | E36: INF | H36: Ethan | I36: Johnson | J36: 2025 | K36: 3 | M36: MINF | Q36: CA | R36: Kings Acdemy | S36: ATL Blue Jays | AA36: JK email notes: 8.5 top 1000. C/1b 6'2" 210
B37: 1 | C37: =IFERROR(__xludf.DUMMYFUNCTION("""COMPUTED_VALUE"""),"Gabe Pegues (3) - '25 COF VA") -> Gabe Pegues (3) - '25 COF VA | D37: Gabe Pegues | E37: OF | H37: Gabe | I37: Pegues | J37: 2025 | K37: 3 | M37: COF | Q37: VA | R37: Stars | S37: McLean HS | AA37: JK- Comfortable on balls in air. Supposedly elite runner. Physical RH hitter. Looks athletic. Below avg arm53 (4.37)/Klook.Poor rating on PG
B38: 1 | C38: =IFERROR(__xludf.DUMMYFUNCTION("""COMPUTED_VALUE"""),"Grant Belcher (3) - '25 RHP CO") -> Grant Belcher (3) - '25 RHP CO | D38: Grant Belcher | E38: RHP | H38: Grant | I38: Belcher | J38: 2025 | K38: 3 | M38: RHP | Q38: CO | R38: Ralston Valley | S38: Elite | AA38: AP: update: slow start to 24 season. lots of BB's/HBP's. not good enough 6'1 180 86-89, 73 -/+ SL, CH. decent FB but got hit. quick arm. Future Gamer. Needs to show success in 24 spring season
B39: 1 | C39: =IFERROR(__xludf.DUMMYFUNCTION("""COMPUTED_VALUE"""),"Jacob Pettit (3) - '25 COF SC") -> Jacob Pettit (3) - '25 COF SC | D39: Jacob Pettit | E39: OF | H39: Jacob | I39: Pettit | J39: 2025 | K39: 3 | M39: COF | Q39: SC | R39: SoChar Panthers | AA39: JK-saw in GA. Switch hitter. May be transitioning to OF. Def. follow if interested. - 368 hitter in 33 PG games in summer.
B40: 1 | C40: =IFERROR(__xludf.DUMMYFUNCTION("""COMPUTED_VALUE"""),"Jaxon Sparks (3) - '25 LHP IN") -> Jaxon Sparks (3) - '25 LHP IN | D40: Jaxon Sparks | E40: LHP | H40: Jaxon | I40: Sparks | J40: 2025 | K40: 3 | M40: LHP | Q40: IN | R40: Carroll (IN) | S40: Indiana Bulls | AA40: AP: rec from Dan Held (Bulls), duel guy. 6'1 215 strong build. mid 80's with decent SL. good HS stats as SO on mound. Runs 6.63! LHH with juice but only hit .270 as SO. outfielder. Future Games. have not seen.
...

Sheet StarUpdater
A1: PASTE UPDATED RANKINGS HERE - They will then appear in Column AJ on Player sheet
A2: Name | B2: Team | C2: Cur ★ | D2: New ★

Sheet Big Board by Position
B1: 0.1 Committed 1 Offer 2 High Follow 3 Follow 4 Need to see XX Commited Elsewhere | H1: RECRUITING BOARD BY POSITION | AJ1: 1
N2: CLASS: | O2: 2027
B3: RHP | H3: LHP | N3: INF | U3: OF | AB3: C
B4: NAME | D4: STATE | E4: TEAM | F4: ★ | H4: NAME | J4: STATE | K4: TEAM | L4: ★ | N4: NAME | P4: B/T | Q4: STATE | R4: TEAM | S4: ★ | U4: NAME | W4: B/T | X4: STATE | Y4: TEAM | Z4: ★ | AB4: NAME | AD4: B/T | AE4: STATE | AF4: TEAM | AG4: ★
B5: =IFERROR(__xludf.DUMMYFUNCTION("iferror(FILTER('High School Players'!$D:$D,$O$2='High School Players'!$J:$J,B3='High School Players'!$M:$M,$AJ$1='High School Players'!$B:$B,'High School Players'!$K:$K<3))"),"Kolby Crosby") -> Kolby Crosby | D5: =IFERROR(__xludf.DUMMYFUNCTION("iferror(FILTER('High School Players'!$Q:$Q,$O$2='High School Players'!$J:$J,B3='High School Players'!$M:$M,$AJ$1='High School Players'!$B:$B,'High School Players'!$K:$K<3))"),"NY") -> NY | E5: =IFERROR(__xludf.DUMMYFUNCTION("iferror(FILTER('High School Players'!$S:$S,$O$2='High School Players'!$J:$J,B3='High School Players'!$M:$M,$AJ$1='High School Players'!$B:$B,'High School Players'!$K:$K<3))"),"TKR Reds") -> TKR Reds | F5: =IFERROR(__xludf.DUMMYFUNCTION("iferror(FILTER('High School Players'!$K:$K,$O$2='High School Players'!$J:$J,B3='High School Players'!$M:$M,$AJ$1='High School Players'!$B:$B,'High School Players'!$K:$K<3))"),0.1) -> 0.1 | H5: =IFERROR(__xludf.DUMMYFUNCTION("iferror(FILTER('High School Players'!$D:$D,$O$2='High School Players'!$J:$J,H3='High School Players'!$M:$M,$AJ$1='High School Players'!$B:$B,'High School Players'!$K:$K<3))"),"Maddux Hasty") -> Maddux Hasty | J5: =IFERROR(__xludf.DUMMYFUNCTION("iferror(FILTER('High School Players'!$Q:$Q,$O$2='High School Players'!$J:$J,H3='High School Players'!$M:$M,$AJ$1='High School Players'!$B:$B,'High School Players'!$K:$K<3))"),"TN") -> TN | K5: =IFERROR(__xludf.DUMMYFUNCTION("iferror(FILTER('High School Players'!$S:$S,$O$2='High School Players'!$J:$J,H3='High School Players'!$M:$M,$AJ$1='High School Players'!$B:$B,'High School Players'!$K:$K<3))"),"") | L5: =IFERROR(__xludf.DUMMYFUNCTION("iferror(FILTER('High School Players'!$K:$K,$O$2='High School Players'!$J:$J,H3='High School Players'!$M:$M,$AJ$1='High School Players'!$B:$B,'High School Players'!$K:$K<3))"),2.0) -> 2 | N5: =IFERROR(__xludf.DUMMYFUNCTION("iferror(FILTER('High School Players'!$D:$D,$O$2='High School Players'!$J:$J,N3='High School Players'!$E:$E,$AJ$1='High School Players'!$B:$B,'High School Players'!$K:$K<3))"),"Zach Madar") -> Zach Madar | P5: =IFERROR(__xludf.DUMMYFUNCTION("iferror(FILTER('High School Players'!$O:$O,$O$2='High School Players'!$J:$J,N3='High School Players'!$E:$E,$AJ$1='High School Players'!$B:$B,'High School Players'!$K:$K<3))"),"R/R") -> R/R | Q5: =IFERROR(__xludf.DUMMYFUNCTION("iferror(FILTER('High School Players'!$Q:$Q,$O$2='High School Players'!$J:$J,N3='High School Players'!$E:$E,$AJ$1='High School Players'!$B:$B,'High School Players'!$K:$K<3))"),"TN") -> TN | R5: =IFERROR(__xludf.DUMMYFUNCTION("iferror(FILTER('High School Players'!$S:$S,$O$2='High School Players'!$J:$J,N3='High School Players'!$E:$E,$AJ$1='High School Players'!$B:$B,'High School Players'!$K:$K<3))"),"FTB Tennessee") -> FTB Tennessee | S5: =IFERROR(__xludf.DUMMYFUNCTION("iferror(FILTER('High School Players'!$K:$K,$O$2='High School Players'!$J:$J,N3='High School Players'!$E:$E,$AJ$1='High School Players'!$B:$B,'High School Players'!$K:$K<3))"),0.1) -> 0.1 | U5: =IFERROR(__xludf.DUMMYFUNCTION("iferror(FILTER('High School Players'!$D:$D,$O$2='High School Players'!$J:$J,U3='High School Players'!$E:$E,$AJ$1='High School Players'!$B:$B,'High School Players'!$K:$K<3))"),"Zachary DeHaas") -> Zachary DeHaas | W5: =IFERROR(__xludf.DUMMYFUNCTION("iferror(FILTER('High School Players'!$O:$O,$O$2='High School Players'!$J:$J,U3='High School Players'!$E:$E,$AJ$1='High School Players'!$B:$B,'High School Players'!$K:$K<3))"),"R/R") -> R/R | X5: =IFERROR(__xludf.DUMMYFUNCTION("iferror(FILTER('High School Players'!$Q:$Q,$O$2='High School Players'!$J:$J,U3='High School Players'!$E:$E,$AJ$1='High School Players'!$B:$B,'High School Players'!$K:$K<3))"),"MO") -> MO | Y5: =IFERROR(__xludf.DUMMYFUNCTION("iferror(FILTER('High School Players'!$S:$S,$O$2='High School Players'!$J:$J,U3='High School Players'!$E:$E,$AJ$1='High School Players'!$B:$B,'High School Players'!$K:$K<3))"),"") | Z5: =IFERROR(__xludf.DUMMYFUNCTION("iferror(FILTER('High School Players'!$K:$K,$O$2='High School Players'!$J:$J,U3='High School Players'!$E:$E,$AJ$1='High School Players'!$B:$B,'High School Players'!$K:$K<3))"),2.0) -> 2 | AB5: =IFERROR(__xludf.DUMMYFUNCTION("iferror(FILTER('High School Players'!$D:$D,$O$2='High School Players'!$J:$J,AB3='High School Players'!$M:$M,$AJ$1='High School Players'!$B:$B,'High School Players'!$K:$K<3))"),"Caleb Flannery") -> Caleb Flannery | AD5: =IFERROR(__xludf.DUMMYFUNCTION("iferror(FILTER('High School Players'!$O:$O,$O$2='High School Players'!$J:$J,AB3='High School Players'!$M:$M,$AJ$1='High School Players'!$B:$B,'High School Players'!$K:$K<3))"),"") | AE5: =IFERROR(__xludf.DUMMYFUNCTION("iferror(FILTER('High School Players'!$Q:$Q,$O$2='High School Players'!$J:$J,AB3='High School Players'!$M:$M,$AJ$1='High School Players'!$B:$B,'High School Players'!$K:$K<3))"),"PA") -> PA | AF5: =IFERROR(__xludf.DUMMYFUNCTION("iferror(FILTER('High School Players'!$S:$S,$O$2='High School Players'!$J:$J,AB3='High School Players'!$M:$M,$AJ$1='High School Players'!$B:$B,'High School Players'!$K:$K<3))"),"") | AG5: =IFERROR(__xludf.DUMMYFUNCTION("iferror(FILTER('High School Players'!$K:$K,$O$2='High School Players'!$J:$J,AB3='High School Players'!$M:$M,$AJ$1='High School Players'!$B:$B,'High School Players'!$K:$K<3))"),0.1) -> 0.1
B6: =IFERROR(__xludf.DUMMYFUNCTION("""COMPUTED_VALUE"""),"Jude Davidson") -> Jude Davidson | D6: =IFERROR(__xludf.DUMMYFUNCTION("""COMPUTED_VALUE"""),"AL") -> AL | E6: =IFERROR(__xludf.DUMMYFUNCTION("""COMPUTED_VALUE"""),"Excel Blue Wave") -> Excel Blue Wave | F6: =IFERROR(__xludf.DUMMYFUNCTION("""COMPUTED_VALUE"""),0.1) -> 0.1 | H6: =IFERROR(__xludf.DUMMYFUNCTION("""COMPUTED_VALUE"""),"Sladen Johnson") -> Sladen Johnson | J6: =IFERROR(__xludf.DUMMYFUNCTION("""COMPUTED_VALUE"""),"MA") -> MA | K6: =IFERROR(__xludf.DUMMYFUNCTION("""COMPUTED_VALUE"""),"Boston Prime") -> Boston Prime | L6: =IFERROR(__xludf.DUMMYFUNCTION("""COMPUTED_VALUE"""),2.0) -> 2 | N6: =IFERROR(__xludf.DUMMYFUNCTION("""COMPUTED_VALUE"""),"Stevie Wellens") -> Stevie Wellens | P6: =IFERROR(__xludf.DUMMYFUNCTION("""COMPUTED_VALUE"""),"R/R") -> R/R | Q6: =IFERROR(__xludf.DUMMYFUNCTION("""COMPUTED_VALUE"""),"CA") -> CA | S6: =IFERROR(__xludf.DUMMYFUNCTION("""COMPUTED_VALUE"""),0.1) -> 0.1 | U6: =IFERROR(__xludf.DUMMYFUNCTION("""COMPUTED_VALUE"""),"Win Hoots") -> Win Hoots | X6: =IFERROR(__xludf.DUMMYFUNCTION("""COMPUTED_VALUE"""),"GA") -> GA | Y6: =IFERROR(__xludf.DUMMYFUNCTION("""COMPUTED_VALUE"""),"643 DP") -> 643 DP | Z6: =IFERROR(__xludf.DUMMYFUNCTION("""COMPUTED_VALUE"""),1.0) -> 1 | AB6: =IFERROR(__xludf.DUMMYFUNCTION("""COMPUTED_VALUE"""),"Parker Filipek") -> Parker Filipek | AD6: =IFERROR(__xludf.DUMMYFUNCTION("""COMPUTED_VALUE"""),"L/R") -> L/R | AE6: =IFERROR(__xludf.DUMMYFUNCTION("""COMPUTED_VALUE"""),"NC") -> NC | AG6: =IFERROR(__xludf.DUMMYFUNCTION("""COMPUTED_VALUE"""),1.0) -> 1
B7: =IFERROR(__xludf.DUMMYFUNCTION("""COMPUTED_VALUE"""),"Jack Van Gemert") -> Jack Van Gemert | D7: =IFERROR(__xludf.DUMMYFUNCTION("""COMPUTED_VALUE"""),"MN") -> MN | E7: =IFERROR(__xludf.DUMMYFUNCTION("""COMPUTED_VALUE"""),"GRB Northstar") -> GRB Northstar | F7: =IFERROR(__xludf.DUMMYFUNCTION("""COMPUTED_VALUE"""),0.1) -> 0.1 | H7: =IFERROR(__xludf.DUMMYFUNCTION("""COMPUTED_VALUE"""),"Owen Sieve") -> Owen Sieve | J7: =IFERROR(__xludf.DUMMYFUNCTION("""COMPUTED_VALUE"""),"TX") -> TX | K7: =IFERROR(__xludf.DUMMYFUNCTION("""COMPUTED_VALUE"""),"Lonestar Baseball Club 2027 National") -> Lonestar Baseball Club 2027 National | L7: =IFERROR(__xludf.DUMMYFUNCTION("""COMPUTED_VALUE"""),2.0) -> 2 | N7: =IFERROR(__xludf.DUMMYFUNCTION("""COMPUTED_VALUE"""),"Bobby Bastek") -> Bobby Bastek | Q7: =IFERROR(__xludf.DUMMYFUNCTION("""COMPUTED_VALUE"""),"GA") -> GA | R7: =IFERROR(__xludf.DUMMYFUNCTION("""COMPUTED_VALUE"""),"643 DP") -> 643 DP | S7: =IFERROR(__xludf.DUMMYFUNCTION("""COMPUTED_VALUE"""),2.0) -> 2 | U7: =IFERROR(__xludf.DUMMYFUNCTION("""COMPUTED_VALUE"""),"Cameron Aguilar") -> Cameron Aguilar | W7: =IFERROR(__xludf.DUMMYFUNCTION("""COMPUTED_VALUE"""),"R/R") -> R/R | X7: =IFERROR(__xludf.DUMMYFUNCTION("""COMPUTED_VALUE"""),"MA") -> MA | Y7: =IFERROR(__xludf.DUMMYFUNCTION("""COMPUTED_VALUE"""),"Nokona") -> Nokona | Z7: =IFERROR(__xludf.DUMMYFUNCTION("""COMPUTED_VALUE"""),2.0) -> 2 | AB7: =IFERROR(__xludf.DUMMYFUNCTION("""COMPUTED_VALUE"""),"Roman Derichsweiler") -> Roman Derichsweiler | AE7: =IFERROR(__xludf.DUMMYFUNCTION("""COMPUTED_VALUE"""),"TX") -> TX | AF7: =IFERROR(__xludf.DUMMYFUNCTION("""COMPUTED_VALUE"""),"Wow Factor Texas 2027") -> Wow Factor Texas 2027 | AG7: =IFERROR(__xludf.DUMMYFUNCTION("""COMPUTED_VALUE"""),2.0) -> 2
B8: =IFERROR(__xludf.DUMMYFUNCTION("""COMPUTED_VALUE"""),"Ethan Wisler") -> Ethan Wisler | D8: =IFERROR(__xludf.DUMMYFUNCTION("""COMPUTED_VALUE"""),"NC") -> NC | E8: =IFERROR(__xludf.DUMMYFUNCTION("""COMPUTED_VALUE"""),"Lynx Baseball") -> Lynx Baseball | F8: =IFERROR(__xludf.DUMMYFUNCTION("""COMPUTED_VALUE"""),0.1) -> 0.1 | H8: =IFERROR(__xludf.DUMMYFUNCTION("""COMPUTED_VALUE"""),"Philip Soltes") -> Philip Soltes | J8: =IFERROR(__xludf.DUMMYFUNCTION("""COMPUTED_VALUE"""),"CT") -> CT | K8: =IFERROR(__xludf.DUMMYFUNCTION("""COMPUTED_VALUE"""),"MVP New England") -> MVP New England | L8: =IFERROR(__xludf.DUMMYFUNCTION("""COMPUTED_VALUE"""),2.0) -> 2 | N8: =IFERROR(__xludf.DUMMYFUNCTION("""COMPUTED_VALUE"""),"Grant Bradley") -> Grant Bradley | Q8: =IFERROR(__xludf.DUMMYFUNCTION("""COMPUTED_VALUE"""),"GA") -> GA | R8: =IFERROR(__xludf.DUMMYFUNCTION("""COMPUTED_VALUE"""),"643 DP") -> 643 DP | S8: =IFERROR(__xludf.DUMMYFUNCTION("""COMPUTED_VALUE"""),1.0) -> 1 | U8: =IFERROR(__xludf.DUMMYFUNCTION("""COMPUTED_VALUE"""),"Matthew Bergin") -> Matthew Bergin | W8: =IFERROR(__xludf.DUMMYFUNCTION("""COMPUTED_VALUE"""),"R/R") -> R/R | Y8: =IFERROR(__xludf.DUMMYFUNCTION("""COMPUTED_VALUE"""),"Boston Prime 17U Navy") -> Boston Prime 17U Navy | Z8: =IFERROR(__xludf.DUMMYFUNCTION("""COMPUTED_VALUE"""),2.0) -> 2 | AB8: =IFERROR(__xludf.DUMMYFUNCTION("""COMPUTED_VALUE"""),"Cruz Garcia") -> Cruz Garcia | AD8: =IFERROR(__xludf.DUMMYFUNCTION("""COMPUTED_VALUE"""),"R/R") -> R/R | AE8: =IFERROR(__xludf.DUMMYFUNCTION("""COMPUTED_VALUE"""),"CA") -> CA | AG8: =IFERROR(__xludf.DUMMYFUNCTION("""COMPUTED_VALUE"""),2.0) -> 2
B9: =IFERROR(__xludf.DUMMYFUNCTION("""COMPUTED_VALUE"""),"Ben Dahlstedt") -> Ben Dahlstedt | D9: =IFERROR(__xludf.DUMMYFUNCTION("""COMPUTED_VALUE"""),"MA") -> MA | E9: =IFERROR(__xludf.DUMMYFUNCTION("""COMPUTED_VALUE"""),"ECNE Expos") -> ECNE Expos | F9: =IFERROR(__xludf.DUMMYFUNCTION("""COMPUTED_VALUE"""),1.0) -> 1 | H9: =IFERROR(__xludf.DUMMYFUNCTION("""COMPUTED_VALUE"""),"Grayson Waters") -> Grayson Waters | J9: =IFERROR(__xludf.DUMMYFUNCTION("""COMPUTED_VALUE"""),"IL") -> IL | K9: =IFERROR(__xludf.DUMMYFUNCTION("""COMPUTED_VALUE"""),"Cangelosi Sparks North 2027") -> Cangelosi Sparks North 2027 | L9: =IFERROR(__xludf.DUMMYFUNCTION("""COMPUTED_VALUE"""),2.0) -> 2 | N9: =IFERROR(__xludf.DUMMYFUNCTION("""COMPUTED_VALUE"""),"Colt Bradshaw") -> Colt Bradshaw | P9: =IFERROR(__xludf.DUMMYFUNCTION("""COMPUTED_VALUE"""),"R/R") -> R/R | Q9: =IFERROR(__xludf.DUMMYFUNCTION("""COMPUTED_VALUE"""),"VA") -> VA | S9: =IFERROR(__xludf.DUMMYFUNCTION("""COMPUTED_VALUE"""),2.0) -> 2 | U9: =IFERROR(__xludf.DUMMYFUNCTION("""COMPUTED_VALUE"""),"Lucas Collure") -> Lucas Collure | W9: =IFERROR(__xludf.DUMMYFUNCTION("""COMPUTED_VALUE"""),"R/R") -> R/R | X9: =IFERROR(__xludf.DUMMYFUNCTION("""COMPUTED_VALUE"""),"NY") -> NY | Z9: =IFERROR(__xludf.DUMMYFUNCTION("""COMPUTED_VALUE"""),2.0) -> 2 | AB9: =IFERROR(__xludf.DUMMYFUNCTION("""COMPUTED_VALUE"""),"Landon Klein") -> Landon Klein | AD9: =IFERROR(__xludf.DUMMYFUNCTION("""COMPUTED_VALUE"""),"R/R") -> R/R | AE9: =IFERROR(__xludf.DUMMYFUNCTION("""COMPUTED_VALUE"""),"WA") -> WA | AG9: =IFERROR(__xludf.DUMMYFUNCTION("""COMPUTED_VALUE"""),2.0) -> 2
B10: =IFERROR(__xludf.DUMMYFUNCTION("""COMPUTED_VALUE"""),"Jaeger Bedford") -> Jaeger Bedford | D10: =IFERROR(__xludf.DUMMYFUNCTION("""COMPUTED_VALUE"""),"FL") -> FL | E10: =IFERROR(__xludf.DUMMYFUNCTION("""COMPUTED_VALUE"""),"Top Tier Roos") -> Top Tier Roos | F10: =IFERROR(__xludf.DUMMYFUNCTION("""COMPUTED_VALUE"""),2.0) -> 2 | H10: =IFERROR(__xludf.DUMMYFUNCTION("""COMPUTED_VALUE"""),"Hutch Weaver") -> Hutch Weaver | J10: =IFERROR(__xludf.DUMMYFUNCTION("""COMPUTED_VALUE"""),"TN") -> TN | K10: =IFERROR(__xludf.DUMMYFUNCTION("""COMPUTED_VALUE"""),"FTB National 2027") -> FTB National 2027 | L10: =IFERROR(__xludf.DUMMYFUNCTION("""COMPUTED_VALUE"""),2.0) -> 2 | N10: =IFERROR(__xludf.DUMMYFUNCTION("""COMPUTED_VALUE"""),"Wesley Dewitt") -> Wesley Dewitt | P10: =IFERROR(__xludf.DUMMYFUNCTION("""COMPUTED_VALUE"""),"L/R") -> L/R | Q10: =IFERROR(__xludf.DUMMYFUNCTION("""COMPUTED_VALUE"""),"UT") -> UT | S10: =IFERROR(__xludf.DUMMYFUNCTION("""COMPUTED_VALUE"""),2.0) -> 2 | U10: =IFERROR(__xludf.DUMMYFUNCTION("""COMPUTED_VALUE"""),"Brayden Goldstein") -> Brayden Goldstein | W10: =IFERROR(__xludf.DUMMYFUNCTION("""COMPUTED_VALUE"""),"L/R") -> L/R | X10: =IFERROR(__xludf.DUMMYFUNCTION("""COMPUTED_VALUE"""),"CA") -> CA | Z10: =IFERROR(__xludf.DUMMYFUNCTION("""COMPUTED_VALUE"""),2.0) -> 2 | AB10: =IFERROR(__xludf.DUMMYFUNCTION("""COMPUTED_VALUE"""),"Cameron Mares") -> Cameron Mares | AD10: =IFERROR(__xludf.DUMMYFUNCTION("""COMPUTED_VALUE"""),"R/R") -> R/R | AE10: =IFERROR(__xludf.DUMMYFUNCTION("""COMPUTED_VALUE"""),"CO") -> CO | AG10: =IFERROR(__xludf.DUMMYFUNCTION("""COMPUTED_VALUE"""),2.0) -> 2
B11: =IFERROR(__xludf.DUMMYFUNCTION("""COMPUTED_VALUE"""),"Connor Christiansen") -> Connor Christiansen | D11: =IFERROR(__xludf.DUMMYFUNCTION("""COMPUTED_VALUE"""),"IN") -> IN | E11: =IFERROR(__xludf.DUMMYFUNCTION("""COMPUTED_VALUE"""),"Canes Midwest") -> Canes Midwest | F11: =IFERROR(__xludf.DUMMYFUNCTION("""COMPUTED_VALUE"""),2.0) -> 2 | H11: =IFERROR(__xludf.DUMMYFUNCTION("""COMPUTED_VALUE"""),"Jackson Wood") -> Jackson Wood | J11: =IFERROR(__xludf.DUMMYFUNCTION("""COMPUTED_VALUE"""),"HI") -> HI | K11: =IFERROR(__xludf.DUMMYFUNCTION("""COMPUTED_VALUE"""),"Hawaii Elite") -> Hawaii Elite | L11: =IFERROR(__xludf.DUMMYFUNCTION("""COMPUTED_VALUE"""),2.0) -> 2 | N11: =IFERROR(__xludf.DUMMYFUNCTION("""COMPUTED_VALUE"""),"Logan Downey") -> Logan Downey | P11: =IFERROR(__xludf.DUMMYFUNCTION("""COMPUTED_VALUE"""),"R/R") -> R/R | Q11: =IFERROR(__xludf.DUMMYFUNCTION("""COMPUTED_VALUE"""),"NJ") -> NJ | R11: =IFERROR(__xludf.DUMMYFUNCTION("""COMPUTED_VALUE"""),"Ghost National 17U Mocha/Mojo") -> Ghost National 17U Mocha/Mojo | S11: =IFERROR(__xludf.DUMMYFUNCTION("""COMPUTED_VALUE"""),2.0) -> 2 | U11: =IFERROR(__xludf.DUMMYFUNCTION("""COMPUTED_VALUE"""),"Ryan Hawken") -> Ryan Hawken | W11: =IFERROR(__xludf.DUMMYFUNCTION("""COMPUTED_VALUE"""),"R/R") -> R/R | X11: =IFERROR(__xludf.DUMMYFUNCTION("""COMPUTED_VALUE"""),"NJ") -> NJ | Y11: =IFERROR(__xludf.DUMMYFUNCTION("""COMPUTED_VALUE"""),"Ghost") -> Ghost | Z11: =IFERROR(__xludf.DUMMYFUNCTION("""COMPUTED_VALUE"""),2.0) -> 2 | AB11: =IFERROR(__xludf.DUMMYFUNCTION("""COMPUTED_VALUE"""),"Eli Quinley") -> Eli Quinley | AD11: =IFERROR(__xludf.DUMMYFUNCTION("""COMPUTED_VALUE"""),"R/R") -> R/R | AE11: =IFERROR(__xludf.DUMMYFUNCTION("""COMPUTED_VALUE"""),"AL") -> AL | AG11: =IFERROR(__xludf.DUMMYFUNCTION("""COMPUTED_VALUE"""),2.0) -> 2
B12: =IFERROR(__xludf.DUMMYFUNCTION("""COMPUTED_VALUE"""),"Caden Christianson") -> Caden Christianson | D12: =IFERROR(__xludf.DUMMYFUNCTION("""COMPUTED_VALUE"""),"CO") -> CO | E12: =IFERROR(__xludf.DUMMYFUNCTION("""COMPUTED_VALUE"""),"East Cobb/SD Padres ST Underclass") -> East Cobb/SD Padres ST Underclass | F12: =IFERROR(__xludf.DUMMYFUNCTION("""COMPUTED_VALUE"""),2.0) -> 2 | H12: =IFERROR(__xludf.DUMMYFUNCTION("""COMPUTED_VALUE"""),"Brayden Rivera") -> Brayden Rivera | J12: =IFERROR(__xludf.DUMMYFUNCTION("""COMPUTED_VALUE"""),"MD") -> MD | K12: =IFERROR(__xludf.DUMMYFUNCTION("""COMPUTED_VALUE"""),"US Elite Mid Atlantic") -> US Elite Mid Atlantic | L12: =IFERROR(__xludf.DUMMYFUNCTION("""COMPUTED_VALUE"""),2.0) -> 2 | N12: =IFERROR(__xludf.DUMMYFUNCTION("""COMPUTED_VALUE"""),"Carter Huff") -> Carter Huff | Q12: =IFERROR(__xludf.DUMMYFUNCTION("""COMPUTED_VALUE"""),"NC") -> NC | R12: =IFERROR(__xludf.DUMMYFUNCTION("""COMPUTED_VALUE"""),"SCP") -> SCP | S12: =IFERROR(__xludf.DUMMYFUNCTION("""COMPUTED_VALUE"""),2.0) -> 2 | U12: =IFERROR(__xludf.DUMMYFUNCTION("""COMPUTED_VALUE"""),"Grant Helms") -> Grant Helms | Y12: =IFERROR(__xludf.DUMMYFUNCTION("""COMPUTED_VALUE"""),"SBA Bolts") -> SBA Bolts | Z12: =IFERROR(__xludf.DUMMYFUNCTION("""COMPUTED_VALUE"""),2.0) -> 2 | AB12: =IFERROR(__xludf.DUMMYFUNCTION("""COMPUTED_VALUE"""),"Jake Lindsey") -> Jake Lindsey | AE12: =IFERROR(__xludf.DUMMYFUNCTION("""COMPUTED_VALUE"""),"MD") -> MD | AF12: =IFERROR(__xludf.DUMMYFUNCTION("""COMPUTED_VALUE"""),"US Elite") -> US Elite | AG12: =IFERROR(__xludf.DUMMYFUNCTION("""COMPUTED_VALUE"""),2.0) -> 2
B13: =IFERROR(__xludf.DUMMYFUNCTION("""COMPUTED_VALUE"""),"Peyton Crews") -> Peyton Crews | D13: =IFERROR(__xludf.DUMMYFUNCTION("""COMPUTED_VALUE"""),"NC") -> NC | E13: =IFERROR(__xludf.DUMMYFUNCTION("""COMPUTED_VALUE"""),"Dirtbags") -> Dirtbags | F13: =IFERROR(__xludf.DUMMYFUNCTION("""COMPUTED_VALUE"""),2.0) -> 2 | H13: =IFERROR(__xludf.DUMMYFUNCTION("""COMPUTED_VALUE"""),"Jack Snakenberg") -> Jack Snakenberg | J13: =IFERROR(__xludf.DUMMYFUNCTION("""COMPUTED_VALUE"""),"TX") -> TX | K13: =IFERROR(__xludf.DUMMYFUNCTION("""COMPUTED_VALUE"""),"Dallas Tigers") -> Dallas Tigers | L13: =IFERROR(__xludf.DUMMYFUNCTION("""COMPUTED_VALUE"""),1.0) -> 1 | N13: =IFERROR(__xludf.DUMMYFUNCTION("""COMPUTED_VALUE"""),"Chayce Kolbert") -> Chayce Kolbert | P13: =IFERROR(__xludf.DUMMYFUNCTION("""COMPUTED_VALUE"""),"R/R") -> R/R | Q13: =IFERROR(__xludf.DUMMYFUNCTION("""COMPUTED_VALUE"""),"NY") -> NY | S13: =IFERROR(__xludf.DUMMYFUNCTION("""COMPUTED_VALUE"""),2.0) -> 2 | U13: =IFERROR(__xludf.DUMMYFUNCTION("""COMPUTED_VALUE"""),"Tyler Honkomp") -> Tyler Honkomp | W13: =IFERROR(__xludf.DUMMYFUNCTION("""COMPUTED_VALUE"""),"R/R") -> R/R | X13: =IFERROR(__xludf.DUMMYFUNCTION("""COMPUTED_VALUE"""),"IA") -> IA | Z13: =IFERROR(__xludf.DUMMYFUNCTION("""COMPUTED_VALUE"""),2.0) -> 2
B14: =IFERROR(__xludf.DUMMYFUNCTION("""COMPUTED_VALUE"""),"Johnny Deaderick") -> Johnny Deaderick | D14: =IFERROR(__xludf.DUMMYFUNCTION("""COMPUTED_VALUE"""),"GA") -> GA | E14: =IFERROR(__xludf.DUMMYFUNCTION("""COMPUTED_VALUE"""),"643 DP") -> 643 DP | F14: =IFERROR(__xludf.DUMMYFUNCTION("""COMPUTED_VALUE"""),2.0) -> 2 | N14: =IFERROR(__xludf.DUMMYFUNCTION("""COMPUTED_VALUE"""),"Justin Labrador") -> Justin Labrador | P14: =IFERROR(__xludf.DUMMYFUNCTION("""COMPUTED_VALUE"""),"R/R") -> R/R | Q14: =IFERROR(__xludf.DUMMYFUNCTION("""COMPUTED_VALUE"""),"NJ") -> NJ | R14: =IFERROR(__xludf.DUMMYFUNCTION("""COMPUTED_VALUE"""),"Diamond Jacks Super 17") -> Diamond Jacks Super 17 | S14: =IFERROR(__xludf.DUMMYFUNCTION("""COMPUTED_VALUE"""),2.0) -> 2 | U14: =IFERROR(__xludf.DUMMYFUNCTION("""COMPUTED_VALUE"""),"Luke Parrish") -> Luke Parrish | X14: =IFERROR(__xludf.DUMMYFUNCTION("""COMPUTED_VALUE"""),"GA") -> GA | Y14: =IFERROR(__xludf.DUMMYFUNCTION("""COMPUTED_VALUE"""),"FL Burn") -> FL Burn | Z14: =IFERROR(__xludf.DUMMYFUNCTION("""COMPUTED_VALUE"""),2.0) -> 2
B15: =IFERROR(__xludf.DUMMYFUNCTION("""COMPUTED_VALUE"""),"Hudson December") -> Hudson December | D15: =IFERROR(__xludf.DUMMYFUNCTION("""COMPUTED_VALUE"""),"CA") -> CA | E15: =IFERROR(__xludf.DUMMYFUNCTION("""COMPUTED_VALUE"""),"PNT") -> PNT | F15: =IFERROR(__xludf.DUMMYFUNCTION("""COMPUTED_VALUE"""),2.0) -> 2 | N15: =IFERROR(__xludf.DUMMYFUNCTION("""COMPUTED_VALUE"""),"Grayson Morris") -> Grayson Morris | Q15: =IFERROR(__xludf.DUMMYFUNCTION("""COMPUTED_VALUE"""),"VA") -> VA | R15: =IFERROR(__xludf.DUMMYFUNCTION("""COMPUTED_VALUE"""),"Ironbridge") -> Ironbridge | S15: =IFERROR(__xludf.DUMMYFUNCTION("""COMPUTED_VALUE"""),2.0) -> 2 | U15: =IFERROR(__xludf.DUMMYFUNCTION("""COMPUTED_VALUE"""),"Mason Sowers") -> Mason Sowers | X15: =IFERROR(__xludf.DUMMYFUNCTION("""COMPUTED_VALUE"""),"CA") -> CA | Z15: =IFERROR(__xludf.DUMMYFUNCTION("""COMPUTED_VALUE"""),2.0) -> 2
B16: =IFERROR(__xludf.DUMMYFUNCTION("""COMPUTED_VALUE"""),"Cade Filleman") -> Cade Filleman | D16: =IFERROR(__xludf.DUMMYFUNCTION("""COMPUTED_VALUE"""),"CO") -> CO | F16: =IFERROR(__xludf.DUMMYFUNCTION("""COMPUTED_VALUE"""),2.0) -> 2 | N16: =IFERROR(__xludf.DUMMYFUNCTION("""COMPUTED_VALUE"""),"Drew Pittman") -> Drew Pittman | P16: =IFERROR(__xludf.DUMMYFUNCTION("""COMPUTED_VALUE"""),"S/R") -> S/R | Q16: =IFERROR(__xludf.DUMMYFUNCTION("""COMPUTED_VALUE"""),"KS") -> KS | S16: =IFERROR(__xludf.DUMMYFUNCTION("""COMPUTED_VALUE"""),2.0) -> 2 | U16: =IFERROR(__xludf.DUMMYFUNCTION("""COMPUTED_VALUE"""),"Carter Taldo") -> Carter Taldo | W16: =IFERROR(__xludf.DUMMYFUNCTION("""COMPUTED_VALUE"""),"R/R") -> R/R | X16: =IFERROR(__xludf.DUMMYFUNCTION("""COMPUTED_VALUE"""),"KS") -> KS | Z16: =IFERROR(__xludf.DUMMYFUNCTION("""COMPUTED_VALUE"""),1.0) -> 1
B17: =IFERROR(__xludf.DUMMYFUNCTION("""COMPUTED_VALUE"""),"Jackson Fulgintine") -> Jackson Fulgintine | D17: =IFERROR(__xludf.DUMMYFUNCTION("""COMPUTED_VALUE"""),"MA") -> MA | E17: =IFERROR(__xludf.DUMMYFUNCTION("""COMPUTED_VALUE"""),"Boston Prime") -> Boston Prime | F17: =IFERROR(__xludf.DUMMYFUNCTION("""COMPUTED_VALUE"""),2.0) -> 2 | N17: =IFERROR(__xludf.DUMMYFUNCTION("""COMPUTED_VALUE"""),"Brennan Walters") -> Brennan Walters | P17: =IFERROR(__xludf.DUMMYFUNCTION("""COMPUTED_VALUE"""),"L/R") -> L/R | Q17: =IFERROR(__xludf.DUMMYFUNCTION("""COMPUTED_VALUE"""),"KY") -> KY | S17: =IFERROR(__xludf.DUMMYFUNCTION("""COMPUTED_VALUE"""),2.0) -> 2 | U17: =IFERROR(__xludf.DUMMYFUNCTION("""COMPUTED_VALUE"""),"Reign Taylor") -> Reign Taylor | X17: =IFERROR(__xludf.DUMMYFUNCTION("""COMPUTED_VALUE"""),"NC") -> NC | Y17: =IFERROR(__xludf.DUMMYFUNCTION("""COMPUTED_VALUE"""),"USA Prime Coastal") -> USA Prime Coastal | Z17: =IFERROR(__xludf.DUMMYFUNCTION("""COMPUTED_VALUE"""),2.0) -> 2
B18: =IFERROR(__xludf.DUMMYFUNCTION("""COMPUTED_VALUE"""),"Reid Gantenbein-Puchi") -> Reid Gantenbein-Puchi | D18: =IFERROR(__xludf.DUMMYFUNCTION("""COMPUTED_VALUE"""),"CA") -> CA | E18: =IFERROR(__xludf.DUMMYFUNCTION("""COMPUTED_VALUE"""),"BPA") -> BPA | F18: =IFERROR(__xludf.DUMMYFUNCTION("""COMPUTED_VALUE"""),2.0) -> 2 | N18: =IFERROR(__xludf.DUMMYFUNCTION("""COMPUTED_VALUE"""),"Ari Wells") -> Ari Wells | P18: =IFERROR(__xludf.DUMMYFUNCTION("""COMPUTED_VALUE"""),"L/L") -> L/L | Q18: =IFERROR(__xludf.DUMMYFUNCTION("""COMPUTED_VALUE"""),"KY") -> KY | S18: =IFERROR(__xludf.DUMMYFUNCTION("""COMPUTED_VALUE"""),2.0) -> 2 | U18: =IFERROR(__xludf.DUMMYFUNCTION("""COMPUTED_VALUE"""),"Joey Terhaar") -> Joey Terhaar | X18: =IFERROR(__xludf.DUMMYFUNCTION("""COMPUTED_VALUE"""),"MN") -> MN | Y18: =IFERROR(__xludf.DUMMYFUNCTION("""COMPUTED_VALUE"""),"Spects National 2027 Marsolek") -> Spects National 2027 Marsolek | Z18: =IFERROR(__xludf.DUMMYFUNCTION("""COMPUTED_VALUE"""),2.0) -> 2
B19: =IFERROR(__xludf.DUMMYFUNCTION("""COMPUTED_VALUE"""),"Carson Glose") -> Carson Glose | D19: =IFERROR(__xludf.DUMMYFUNCTION("""COMPUTED_VALUE"""),"PA") -> PA | F19: =IFERROR(__xludf.DUMMYFUNCTION("""COMPUTED_VALUE"""),2.0) -> 2 | N19: =IFERROR(__xludf.DUMMYFUNCTION("""COMPUTED_VALUE"""),"Brady Mamula") -> Brady Mamula | P19: =IFERROR(__xludf.DUMMYFUNCTION("""COMPUTED_VALUE"""),"R/R") -> R/R | Q19: =IFERROR(__xludf.DUMMYFUNCTION("""COMPUTED_VALUE"""),"MD") -> MD | R19: =IFERROR(__xludf.DUMMYFUNCTION("""COMPUTED_VALUE"""),"Dirtbags Platinum ") -> Dirtbags Platinum | S19: =IFERROR(__xludf.DUMMYFUNCTION("""COMPUTED_VALUE"""),2.0) -> 2 | U19: =IFERROR(__xludf.DUMMYFUNCTION("""COMPUTED_VALUE"""),"Walker Waggoner") -> Walker Waggoner | W19: =IFERROR(__xludf.DUMMYFUNCTION("""COMPUTED_VALUE"""),"R/R") -> R/R | X19: =IFERROR(__xludf.DUMMYFUNCTION("""COMPUTED_VALUE"""),"GA") -> GA | Y19: =IFERROR(__xludf.DUMMYFUNCTION("""COMPUTED_VALUE"""),"East Cobb Yankees") -> East Cobb Yankees | Z19: =IFERROR(__xludf.DUMMYFUNCTION("""COMPUTED_VALUE"""),2.0) -> 2
B20: =IFERROR(__xludf.DUMMYFUNCTION("""COMPUTED_VALUE"""),"Palmer Gobble") -> Palmer Gobble | D20: =IFERROR(__xludf.DUMMYFUNCTION("""COMPUTED_VALUE"""),"VA") -> VA | E20: =IFERROR(__xludf.DUMMYFUNCTION("""COMPUTED_VALUE"""),"Dirtbags 2027 Platinum") -> Dirtbags 2027 Platinum | F20: =IFERROR(__xludf.DUMMYFUNCTION("""COMPUTED_VALUE"""),2.0) -> 2 | N20: =IFERROR(__xludf.DUMMYFUNCTION("""COMPUTED_VALUE"""),"Kohen Madden") -> Kohen Madden | Q20: =IFERROR(__xludf.DUMMYFUNCTION("""COMPUTED_VALUE"""),"MD") -> MD | R20: =IFERROR(__xludf.DUMMYFUNCTION("""COMPUTED_VALUE"""),"Ole Liners") -> Ole Liners | S20: =IFERROR(__xludf.DUMMYFUNCTION("""COMPUTED_VALUE"""),2.0) -> 2 | U20: =IFERROR(__xludf.DUMMYFUNCTION("""COMPUTED_VALUE"""),"Carston Wedemeyer") -> Carston Wedemeyer | X20: =IFERROR(__xludf.DUMMYFUNCTION("""COMPUTED_VALUE"""),"NC") -> NC | Y20: =IFERROR(__xludf.DUMMYFUNCTION("""COMPUTED_VALUE"""),"SBA Bolts National 2027") -> SBA Bolts National 2027 | Z20: =IFERROR(__xludf.DUMMYFUNCTION("""COMPUTED_VALUE"""),2.0) -> 2
B21: =IFERROR(__xludf.DUMMYFUNCTION("""COMPUTED_VALUE"""),"Will Hayes") -> Will Hayes | D21: =IFERROR(__xludf.DUMMYFUNCTION("""COMPUTED_VALUE"""),"CO") -> CO | F21: =IFERROR(__xludf.DUMMYFUNCTION("""COMPUTED_VALUE"""),2.0) -> 2 | N21: =IFERROR(__xludf.DUMMYFUNCTION("""COMPUTED_VALUE"""),"Bryce Fontenot") -> Bryce Fontenot | Q21: =IFERROR(__xludf.DUMMYFUNCTION("""COMPUTED_VALUE"""),"GA") -> GA | R21: =IFERROR(__xludf.DUMMYFUNCTION("""COMPUTED_VALUE"""),"USA Scout National") -> USA Scout National | S21: =IFERROR(__xludf.DUMMYFUNCTION("""COMPUTED_VALUE"""),2.0) -> 2 | U21: =IFERROR(__xludf.DUMMYFUNCTION("""COMPUTED_VALUE"""),"Jackson Bailey") -> Jackson Bailey | X21: =IFERROR(__xludf.DUMMYFUNCTION("""COMPUTED_VALUE"""),"SC") -> SC | Y21: =IFERROR(__xludf.DUMMYFUNCTION("""COMPUTED_VALUE"""),"South Charlotte Panthers") -> South Charlotte Panthers | Z21: =IFERROR(__xludf.DUMMYFUNCTION("""COMPUTED_VALUE"""),2.0) -> 2
B22: =IFERROR(__xludf.DUMMYFUNCTION("""COMPUTED_VALUE"""),"Thurston Kiefer") -> Thurston Kiefer | D22: =IFERROR(__xludf.DUMMYFUNCTION("""COMPUTED_VALUE"""),"MA") -> MA | E22: =IFERROR(__xludf.DUMMYFUNCTION("""COMPUTED_VALUE"""),"Boston Prime") -> Boston Prime | F22: =IFERROR(__xludf.DUMMYFUNCTION("""COMPUTED_VALUE"""),2.0) -> 2 | N22: =IFERROR(__xludf.DUMMYFUNCTION("""COMPUTED_VALUE"""),"Rylin Lyemance") -> Rylin Lyemance | Q22: =IFERROR(__xludf.DUMMYFUNCTION("""COMPUTED_VALUE"""),"GA") -> GA | R22: =IFERROR(__xludf.DUMMYFUNCTION("""COMPUTED_VALUE"""),"USA Scout National") -> USA Scout National | S22: =IFERROR(__xludf.DUMMYFUNCTION("""COMPUTED_VALUE"""),1.0) -> 1 | U22: =IFERROR(__xludf.DUMMYFUNCTION("""COMPUTED_VALUE"""),"Braden Little") -> Braden Little | X22: =IFERROR(__xludf.DUMMYFUNCTION("""COMPUTED_VALUE"""),"GA") -> GA | Y22: =IFERROR(__xludf.DUMMYFUNCTION("""COMPUTED_VALUE"""),"USA Scout National") -> USA Scout National | Z22: =IFERROR(__xludf.DUMMYFUNCTION("""COMPUTED_VALUE"""),1.0) -> 1
B23: =IFERROR(__xludf.DUMMYFUNCTION("""COMPUTED_VALUE"""),"Robert Kilpatrick") -> Robert Kilpatrick | D23: =IFERROR(__xludf.DUMMYFUNCTION("""COMPUTED_VALUE"""),"VA") -> VA | E23: =IFERROR(__xludf.DUMMYFUNCTION("""COMPUTED_VALUE"""),"Prime Time Aces") -> Prime Time Aces | F23: =IFERROR(__xludf.DUMMYFUNCTION("""COMPUTED_VALUE"""),2.0) -> 2 | N23: =IFERROR(__xludf.DUMMYFUNCTION("""COMPUTED_VALUE"""),"Jameson Mayfield") -> Jameson Mayfield | Q23: =IFERROR(__xludf.DUMMYFUNCTION("""COMPUTED_VALUE"""),"TX") -> TX | R23: =IFERROR(__xludf.DUMMYFUNCTION("""COMPUTED_VALUE"""),"Dallas Tigers") -> Dallas Tigers | S23: =IFERROR(__xludf.DUMMYFUNCTION("""COMPUTED_VALUE"""),1.0) -> 1 | U23: =IFERROR(__xludf.DUMMYFUNCTION("""COMPUTED_VALUE"""),"Chance Williams") -> Chance Williams | X23: =IFERROR(__xludf.DUMMYFUNCTION("""COMPUTED_VALUE"""),"GA") -> GA | Y23: =IFERROR(__xludf.DUMMYFUNCTION("""COMPUTED_VALUE"""),"USA Scout National") -> USA Scout National | Z23: =IFERROR(__xludf.DUMMYFUNCTION("""COMPUTED_VALUE"""),1.0) -> 1
B24: =IFERROR(__xludf.DUMMYFUNCTION("""COMPUTED_VALUE"""),"Wyatt Libbert") -> Wyatt Libbert | D24: =IFERROR(__xludf.DUMMYFUNCTION("""COMPUTED_VALUE"""),"MO") -> MO | E24: =IFERROR(__xludf.DUMMYFUNCTION("""COMPUTED_VALUE"""),"Royals Scout Team ") -> Royals Scout Team | F24: =IFERROR(__xludf.DUMMYFUNCTION("""COMPUTED_VALUE"""),2.0) -> 2 | N24: =IFERROR(__xludf.DUMMYFUNCTION("""COMPUTED_VALUE"""),"Cole Schott") -> Cole Schott | Q24: =IFERROR(__xludf.DUMMYFUNCTION("""COMPUTED_VALUE"""),"TX") -> TX | R24: =IFERROR(__xludf.DUMMYFUNCTION("""COMPUTED_VALUE"""),"Dallas Tigers") -> Dallas Tigers | S24: =IFERROR(__xludf.DUMMYFUNCTION("""COMPUTED_VALUE"""),1.0) -> 1 | U24: =IFERROR(__xludf.DUMMYFUNCTION("""COMPUTED_VALUE"""),"Makayle Moon") -> Makayle Moon | X24: =IFERROR(__xludf.DUMMYFUNCTION("""COMPUTED_VALUE"""),"SC") -> SC | Y24: =IFERROR(__xludf.DUMMYFUNCTION("""COMPUTED_VALUE"""),"USA Scout National") -> USA Scout National | Z24: =IFERROR(__xludf.DUMMYFUNCTION("""COMPUTED_VALUE"""),2.0) -> 2
B25: =IFERROR(__xludf.DUMMYFUNCTION("""COMPUTED_VALUE"""),"Hayden Moore") -> Hayden Moore | D25: =IFERROR(__xludf.DUMMYFUNCTION("""COMPUTED_VALUE"""),"NC") -> NC | E25: =IFERROR(__xludf.DUMMYFUNCTION("""COMPUTED_VALUE"""),"SCP") -> SCP | F25: =IFERROR(__xludf.DUMMYFUNCTION("""COMPUTED_VALUE"""),2.0) -> 2 | N25: =IFERROR(__xludf.DUMMYFUNCTION("""COMPUTED_VALUE"""),"Connor Jennings") -> Connor Jennings | Q25: =IFERROR(__xludf.DUMMYFUNCTION("""COMPUTED_VALUE"""),"TX") -> TX | R25: =IFERROR(__xludf.DUMMYFUNCTION("""COMPUTED_VALUE"""),"Dallas Tigers") -> Dallas Tigers | S25: =IFERROR(__xludf.DUMMYFUNCTION("""COMPUTED_VALUE"""),2.0) -> 2 | U25: =IFERROR(__xludf.DUMMYFUNCTION("""COMPUTED_VALUE"""),"Reid Williams") -> Reid Williams | X25: =IFERROR(__xludf.DUMMYFUNCTION("""COMPUTED_VALUE"""),"TX") -> TX | Y25: =IFERROR(__xludf.DUMMYFUNCTION("""COMPUTED_VALUE"""),"Dallas Tigers") -> Dallas Tigers | Z25: =IFERROR(__xludf.DUMMYFUNCTION("""COMPUTED_VALUE"""),1.0) -> 1
B26: =IFERROR(__xludf.DUMMYFUNCTION("""COMPUTED_VALUE"""),"Winston Patterson") -> Winston Patterson | D26: =IFERROR(__xludf.DUMMYFUNCTION("""COMPUTED_VALUE"""),"CO") -> CO | E26: =IFERROR(__xludf.DUMMYFUNCTION("""COMPUTED_VALUE"""),"Franklin Scout Team") -> Franklin Scout Team | F26: =IFERROR(__xludf.DUMMYFUNCTION("""COMPUTED_VALUE"""),2.0) -> 2 | N26: =IFERROR(__xludf.DUMMYFUNCTION("""COMPUTED_VALUE"""),"Hudson Hardesty") -> Hudson Hardesty | Q26: =IFERROR(__xludf.DUMMYFUNCTION("""COMPUTED_VALUE"""),"MO") -> MO | R26: =IFERROR(__xludf.DUMMYFUNCTION("""COMPUTED_VALUE"""),"Royals Scout Team ") -> Royals Scout Team | S26: =IFERROR(__xludf.DUMMYFUNCTION("""COMPUTED_VALUE"""),2.0) -> 2 | U26: =IFERROR(__xludf.DUMMYFUNCTION("""COMPUTED_VALUE"""),"Carson Roy") -> Carson Roy | X26: =IFERROR(__xludf.DUMMYFUNCTION("""COMPUTED_VALUE"""),"TX") -> TX | Y26: =IFERROR(__xludf.DUMMYFUNCTION("""COMPUTED_VALUE"""),"Dallas Tigers") -> Dallas Tigers | Z26: =IFERROR(__xludf.DUMMYFUNCTION("""COMPUTED_VALUE"""),1.0) -> 1
B27: =IFERROR(__xludf.DUMMYFUNCTION("""COMPUTED_VALUE"""),"Nolan Plourde") -> Nolan Plourde | D27: =IFERROR(__xludf.DUMMYFUNCTION("""COMPUTED_VALUE"""),"CT") -> CT | F27: =IFERROR(__xludf.DUMMYFUNCTION("""COMPUTED_VALUE"""),2.0) -> 2 | N27: =IFERROR(__xludf.DUMMYFUNCTION("""COMPUTED_VALUE"""),"Mason Borders") -> Mason Borders | Q27: =IFERROR(__xludf.DUMMYFUNCTION("""COMPUTED_VALUE"""),"TN") -> TN | R27: =IFERROR(__xludf.DUMMYFUNCTION("""COMPUTED_VALUE"""),"Rawlings SE MAD Mavericks") -> Rawlings SE MAD Mavericks | S27: =IFERROR(__xludf.DUMMYFUNCTION("""COMPUTED_VALUE"""),2.0) -> 2 | U27: =IFERROR(__xludf.DUMMYFUNCTION("""COMPUTED_VALUE"""),"Owen Lester") -> Owen Lester | X27: =IFERROR(__xludf.DUMMYFUNCTION("""COMPUTED_VALUE"""),"KS") -> KS | Y27: =IFERROR(__xludf.DUMMYFUNCTION("""COMPUTED_VALUE"""),"Royals Scout Team ") -> Royals Scout Team | Z27: =IFERROR(__xludf.DUMMYFUNCTION("""COMPUTED_VALUE"""),1.0) -> 1
B28: =IFERROR(__xludf.DUMMYFUNCTION("""COMPUTED_VALUE"""),"Luke Rafferty") -> Luke Rafferty | D28: =IFERROR(__xludf.DUMMYFUNCTION("""COMPUTED_VALUE"""),"TX") -> TX | E28: =IFERROR(__xludf.DUMMYFUNCTION("""COMPUTED_VALUE"""),"Boston Prime") -> Boston Prime | F28: =IFERROR(__xludf.DUMMYFUNCTION("""COMPUTED_VALUE"""),2.0) -> 2 | N28: =IFERROR(__xludf.DUMMYFUNCTION("""COMPUTED_VALUE"""),"Ty Lange") -> Ty Lange | Q28: =IFERROR(__xludf.DUMMYFUNCTION("""COMPUTED_VALUE"""),"MO") -> MO | R28: =IFERROR(__xludf.DUMMYFUNCTION("""COMPUTED_VALUE"""),"Team KC 2027") -> Team KC 2027 | S28: =IFERROR(__xludf.DUMMYFUNCTION("""COMPUTED_VALUE"""),2.0) -> 2 | U28: =IFERROR(__xludf.DUMMYFUNCTION("""COMPUTED_VALUE"""),"Carson Reffel") -> Carson Reffel | X28: =IFERROR(__xludf.DUMMYFUNCTION("""COMPUTED_VALUE"""),"CO") -> CO | Y28: =IFERROR(__xludf.DUMMYFUNCTION("""COMPUTED_VALUE"""),"Slammers") -> Slammers | Z28: =IFERROR(__xludf.DUMMYFUNCTION("""COMPUTED_VALUE"""),2.0) -> 2
B29: =IFERROR(__xludf.DUMMYFUNCTION("""COMPUTED_VALUE"""),"Braden Richardson") -> Braden Richardson | D29: =IFERROR(__xludf.DUMMYFUNCTION("""COMPUTED_VALUE"""),"SC") -> SC | E29: =IFERROR(__xludf.DUMMYFUNCTION("""COMPUTED_VALUE"""),"CBA Orioles") -> CBA Orioles | F29: =IFERROR(__xludf.DUMMYFUNCTION("""COMPUTED_VALUE"""),2.0) -> 2 | N29: =IFERROR(__xludf.DUMMYFUNCTION("""COMPUTED_VALUE"""),"Ryan Kume") -> Ryan Kume | Q29: =IFERROR(__xludf.DUMMYFUNCTION("""COMPUTED_VALUE"""),"TX") -> TX | R29: =IFERROR(__xludf.DUMMYFUNCTION("""COMPUTED_VALUE"""),"Lonestar Baseball Club") -> Lonestar Baseball Club | S29: =IFERROR(__xludf.DUMMYFUNCTION("""COMPUTED_VALUE"""),2.0) -> 2 | U29: =IFERROR(__xludf.DUMMYFUNCTION("""COMPUTED_VALUE"""),"Ayden Collier") -> Ayden Collier | X29: =IFERROR(__xludf.DUMMYFUNCTION("""COMPUTED_VALUE"""),"TX") -> TX | Y29: =IFERROR(__xludf.DUMMYFUNCTION("""COMPUTED_VALUE"""),"Wildcatters") -> Wildcatters | Z29: =IFERROR(__xludf.DUMMYFUNCTION("""COMPUTED_VALUE"""),1.0) -> 1
B30: =IFERROR(__xludf.DUMMYFUNCTION("""COMPUTED_VALUE"""),"Tyler Roach") -> Tyler Roach | D30: =IFERROR(__xludf.DUMMYFUNCTION("""COMPUTED_VALUE"""),"LA") -> LA | F30: =IFERROR(__xludf.DUMMYFUNCTION("""COMPUTED_VALUE"""),2.0) -> 2 | N30: =IFERROR(__xludf.DUMMYFUNCTION("""COMPUTED_VALUE"""),"Finn Torvik") -> Finn Torvik | Q30: =IFERROR(__xludf.DUMMYFUNCTION("""COMPUTED_VALUE"""),"CO") -> CO | R30: =IFERROR(__xludf.DUMMYFUNCTION("""COMPUTED_VALUE"""),"Slammers") -> Slammers | S30: =IFERROR(__xludf.DUMMYFUNCTION("""COMPUTED_VALUE"""),2.0) -> 2 | U30: =IFERROR(__xludf.DUMMYFUNCTION("""COMPUTED_VALUE"""),"Miles Norman") -> Miles Norman | X30: =IFERROR(__xludf.DUMMYFUNCTION("""COMPUTED_VALUE"""),"GA") -> GA | Y30: =IFERROR(__xludf.DUMMYFUNCTION("""COMPUTED_VALUE"""),"5 Star Mafia") -> 5 Star Mafia | Z30: =IFERROR(__xludf.DUMMYFUNCTION("""COMPUTED_VALUE"""),1.0) -> 1
B31: =IFERROR(__xludf.DUMMYFUNCTION("""COMPUTED_VALUE"""),"Sully Townley") -> Sully Townley | D31: =IFERROR(__xludf.DUMMYFUNCTION("""COMPUTED_VALUE"""),"SC") -> SC | E31: =IFERROR(__xludf.DUMMYFUNCTION("""COMPUTED_VALUE"""),"Palmetto Blacksmiths SC 2027") -> Palmetto Blacksmiths SC 2027 | F31: =IFERROR(__xludf.DUMMYFUNCTION("""COMPUTED_VALUE"""),2.0) -> 2 | N31: =IFERROR(__xludf.DUMMYFUNCTION("""COMPUTED_VALUE"""),"Koa Peters") -> Koa Peters | Q31: =IFERROR(__xludf.DUMMYFUNCTION("""COMPUTED_VALUE"""),"GA") -> GA | S31: =IFERROR(__xludf.DUMMYFUNCTION("""COMPUTED_VALUE"""),2.0) -> 2 | U31: =IFERROR(__xludf.DUMMYFUNCTION("""COMPUTED_VALUE"""),"Logan Grubbs") -> Logan Grubbs | X31: =IFERROR(__xludf.DUMMYFUNCTION("""COMPUTED_VALUE"""),"NV") -> NV | Y31: =IFERROR(__xludf.DUMMYFUNCTION("""COMPUTED_VALUE"""),"5 Star") -> 5 Star | Z31: =IFERROR(__xludf.DUMMYFUNCTION("""COMPUTED_VALUE"""),2.0) -> 2
B32: =IFERROR(__xludf.DUMMYFUNCTION("""COMPUTED_VALUE"""),"Cooper Mengel") -> Cooper Mengel | D32: =IFERROR(__xludf.DUMMYFUNCTION("""COMPUTED_VALUE"""),"MD") -> MD | E32: =IFERROR(__xludf.DUMMYFUNCTION("""COMPUTED_VALUE"""),"DCP") -> DCP | F32: =IFERROR(__xludf.DUMMYFUNCTION("""COMPUTED_VALUE"""),2.0) -> 2
B33: =IFERROR(__xludf.DUMMYFUNCTION("""COMPUTED_VALUE"""),"Ethan Noyes") -> Ethan Noyes | D33: =IFERROR(__xludf.DUMMYFUNCTION("""COMPUTED_VALUE"""),"MD") -> MD | F33: =IFERROR(__xludf.DUMMYFUNCTION("""COMPUTED_VALUE"""),2.0) -> 2
B34: =IFERROR(__xludf.DUMMYFUNCTION("""COMPUTED_VALUE"""),"Kason Webb") -> Kason Webb | D34: =IFERROR(__xludf.DUMMYFUNCTION("""COMPUTED_VALUE"""),"AZ") -> AZ | E34: =IFERROR(__xludf.DUMMYFUNCTION("""COMPUTED_VALUE"""),"California PFA") -> California PFA | F34: =IFERROR(__xludf.DUMMYFUNCTION("""COMPUTED_VALUE"""),2.0) -> 2
B35: =IFERROR(__xludf.DUMMYFUNCTION("""COMPUTED_VALUE"""),"Jack Burke") -> Jack Burke | D35: =IFERROR(__xludf.DUMMYFUNCTION("""COMPUTED_VALUE"""),"GA") -> GA | E35: =IFERROR(__xludf.DUMMYFUNCTION("""COMPUTED_VALUE"""),"USA Scout National") -> USA Scout National | F35: =IFERROR(__xludf.DUMMYFUNCTION("""COMPUTED_VALUE"""),2.0) -> 2
B36: =IFERROR(__xludf.DUMMYFUNCTION("""COMPUTED_VALUE"""),"Jackson Barker") -> Jackson Barker | D36: =IFERROR(__xludf.DUMMYFUNCTION("""COMPUTED_VALUE"""),"KS") -> KS | E36: =IFERROR(__xludf.DUMMYFUNCTION("""COMPUTED_VALUE"""),"Building Champions") -> Building Champions | F36: =IFERROR(__xludf.DUMMYFUNCTION("""COMPUTED_VALUE"""),2.0) -> 2
B37: =IFERROR(__xludf.DUMMYFUNCTION("""COMPUTED_VALUE"""),"Peyton Landers") -> Peyton Landers | D37: =IFERROR(__xludf.DUMMYFUNCTION("""COMPUTED_VALUE"""),"FL") -> FL | E37: =IFERROR(__xludf.DUMMYFUNCTION("""COMPUTED_VALUE"""),"Lousiville Baseball Club National") -> Lousiville Baseball Club National | F37: =IFERROR(__xludf.DUMMYFUNCTION("""COMPUTED_VALUE"""),2.0) -> 2
